#VRML_SIM R2021a utf8
WorldInfo {
  coordinateSystem "NUE"
}
Viewpoint {
  orientation 0.9996486351216851 0.013958725431132055 -0.022533536865974896 5.36837972407527
  position -0.10823714955706289 1.628805270672941 0.9948928506590944
}
TexturedBackground {
}
TexturedBackgroundLight {
}
RectangleArena {
}
DEF gate Robot {
  children [
    Transform {
      translation 0 0.03 0
      children [
        DEF bottom Shape {
          appearance PBRAppearance {
            baseColor 0.341176 0.172549 0
            roughness 0.9
            metalness 0
          }
          geometry Box {
            size 0.05 0.05 0.05
          }
        }
      ]
    }
    HingeJoint {
      jointParameters HingeJointParameters {
        position 1
        axis 0 0 1
        anchor 0 0.03 0.04
      }
      device [
        RotationalMotor {
          name "gateMotor"
        }
        PositionSensor {
          name "ps"
        }
      ]
      endPoint Solid {
        translation 0.09725441505626514 0.18146477726542137 0.04
        rotation 0 0 1 0.9999999999999998
        children [
          DEF gate Shape {
            appearance PBRAppearance {
              baseColor 1 0 0
              roughness 0.9
              metalness 0
            }
            geometry Box {
              size 0.4 0.03 0.01
            }
          }
        ]
        boundingObject USE gate
        physics Physics {
        }
      }
    }
  ]
  boundingObject USE bottom
  physics Physics {
  }
}
